Workbook

Sheet cat_lang
A1: lang_code | B1: lang_id | C1: lang_label
A2: en | B2: 1 | C2: English
A3: es | B3: =B2+1 -> 2 | C3: Español
B4: =B3+1 -> 3
B5: =B4+1 -> 4
B6: =B5+1 -> 5
B7: =B6+1 -> 6
B8: =B7+1 -> 7
B9: =B8+1 -> 8
B10: =B9+1 -> 9
B11: =B10+1 -> 10
B12: =B11+1 -> 11
B13: =B12+1 -> 12
B14: =B13+1 -> 13
B15: =B14+1 -> 14
... B1001: =B1000+1 -> 1000

Sheet cat_context_class
A1: context_class_code | B1: context_class_id
A2: MMSS | B2: 5000
B3: =B2+1 -> 5001
B4: =B3+1 -> 5002
B5: =B4+1 -> 5003
B6: =B5+1 -> 5004
B7: =B6+1 -> 5005
B8: =B7+1 -> 5006
B9: =B8+1 -> 5007
B10: =B9+1 -> 5008
B11: =B10+1 -> 5009
B12: =B11+1 -> 5010
B13: =B12+1 -> 5011
B14: =B13+1 -> 5012
... B1001: =B1000+1 -> 5999

Sheet cat_context
A1: context_code | B1: context_id | C1: context_class_id | D1: context_class_code
A2: Lineas | B2: 1 | C2: =VLOOKUP(D2,cat_context_class!$A$2:$B$1001,2,0) -> 5000 | D2: MMSS
A3: Metodos | B3: =B2+1 -> 2 | C3: =VLOOKUP(D3,cat_context_class!$A$2:$B$1001,2,0) -> 5000 | D3: MMSS
A4: Objetos | B4: =B3+1 -> 3 | C4: =VLOOKUP(D4,cat_context_class!$A$2:$B$1001,2,0) -> 5000 | D4: MMSS
B5: =B4+1 -> 4 | C5: =VLOOKUP(D5,cat_context_class!$A$2:$B$1001,2,0) -> 5000 | D5: MMSS
B6: =B5+1 -> 5 | C6: =VLOOKUP(D6,cat_context_class!$A$2:$B$1001,2,0) -> 5000 | D6: MMSS
B7: =B6+1 -> 6 | C7: =VLOOKUP(D7,cat_context_class!$A$2:$B$1001,2,0) -> #N/A
B8: =B7+1 -> 7 | C8: =VLOOKUP(D8,cat_context_class!$A$2:$B$1001,2,0) -> #N/A
B9: =B8+1 -> 8 | C9: =VLOOKUP(D9,cat_context_class!$A$2:$B$1001,2,0) -> #N/A
B10: =B9+1 -> 9 | C10: =VLOOKUP(D10,cat_context_class!$A$2:$B$1001,2,0) -> #N/A
B11: =B10+1 -> 10 | C11: =VLOOKUP(D11,cat_context_class!$A$2:$B$1001,2,0) -> #N/A
B12: =B11+1 -> 11 | C12: =VLOOKUP(D12,cat_context_class!$A$2:$B$1001,2,0) -> #N/A
B13: =B12+1 -> 12 | C13: =VLOOKUP(D13,cat_context_class!$A$2:$B$1001,2,0) -> #N/A
B14: =B13+1 -> 13 | C14: =VLOOKUP(D14,cat_context_class!$A$2:$B$1001,2,0) -> #N/A
B15: =B14+1 -> 14 | C15: =VLOOKUP(D15,cat_context_class!$A$2:$B$1001,2,0) -> #N/A
B16: =B15+1 -> 15 | C16: =VLOOKUP(D16,cat_context_class!$A$2:$B$1001,2,0) -> #N/A
B17: =B16+1 -> 16 | C17: =VLOOKUP(D17,cat_context_class!$A$2:$B$1001,2,0) -> #N/A
B18: =B17+1 -> 17 | C18: =VLOOKUP(D18,cat_context_class!$A$2:$B$1001,2,0) -> #N/A
... B1001: =B1000+1 -> 1000 | C1001: =VLOOKUP(D1001,cat_context_class!$A$2:$B$1001,2,0) -> #N/A

Sheet cat_object
A1: object_code | B1: object_id | C1: object_label_en | D1: object_label_es | E1: object_desc_en | F1: object_desc_es | G1: reference | H1: year
A2: Alejandro_Ruiz | B2: 1001 | C2: Alejandro Ruiz | D2: Alejandro Ruiz | E2: Alejandro Arnulfo Ruiz León | F2: Alejandro Arnulfo Ruiz León
A3: Aline_Saldaña | B3: =B2+1 -> 1002 | C3: Aline Saldaña | D3: Aline Saldaña | E3: Aline Amor Saldaña Sánchez | F3: Aline Amor Saldaña Sánchez
A4: Ana_Medeles | B4: =B3+1 -> 1003 | C4: Ana Medeles | D4: Ana Medeles | E4: Ana María Medeles Hernández | F4: Ana María Medeles Hernández
A5: Carlos_Rodriguez | B5: =B4+1 -> 1004 | C5: Carlos Rodriguez | D5: Carlos Rodriguez | E5: Carlos Rodríguez Contreras | F5: Carlos Rodríguez Contreras
A6: Cristina_Jasso | B6: =B5+1 -> 1005 | C6: Cristina Jasso | D6: Cristina Jasso | E6: Cristina Jasso del Toro | F6: Cristina Jasso del Toro
A7: Diana_Sheinbaum | B7: =B6+1 -> 1006 | C7: Diana Sheinbaum | D7: Diana Sheinbaum | E7: Diana Sheinbaum Lerner | F7: Diana Sheinbaum Lerner
A8: Eduardo_Robles | B8: =B7+1 -> 1007 | C8: Eduardo Robles | D8: Eduardo Robles | E8: Eduardo Robles Belmont | F8: Eduardo Robles Belmont
A9: Enrique_Perez | B9: =B8+1 -> 1008 | C9: Enrique Perez | D9: Enrique Perez | E9: Enrique Felipe Pérez García | F9: Enrique Felipe Pérez García
A10: Frida_Gorbach | B10: =B9+1 -> 1009 | C10: Frida Gorbach | D10: Frida Gorbach | E10: Frida Gorbach Rudoy | F10: Frida Gorbach Rudoy
A11: Gabriel_Ramos | B11: =B10+1 -> 1010 | C11: Gabriel Ramos | D11: Gabriel Ramos | E11: Gabriel Ramos Fernández | F11: Gabriel Ramos Fernández
A12: Gabriela_Sued | B12: =B11+1 -> 1011 | C12: Gabriela Sued | D12: Gabriela Sued | E12: Gabriela Elisa Sued | F12: Gabriela Elisa Sued
A13: Guillermina_Castro | B13: =B12+1 -> 1012 | C13: Guillermina Castro | D13: Guillermina Castro | E13: Guillermina Castro Nieto | F13: Guillermina Castro Nieto
A14: Guillermo_Espinosa | B14: =B13+1 -> 1013 | C14: Guillermo Espinosa | D14: Guillermo Espinosa | E14: Guillermo Andrés Espinosa Velazco | F14: Guillermo Andrés Espinosa Velazco
... A29: Lilia_Ponce | B29: =B28+1 -> 1028 | C29: Lilia Ponce de León | D29: Lilia Ponce de León | E29: Lilia Ponce de León García | F29: Lilia Ponce de León García
A30: Liliana_Ramirez | B30: =B29+1 -> 1029 | C30: Liliana Ramírez | D30: Liliana Ramírez | E30: Liliana Ramírez Ruíz | F30: Liliana Ramírez Ruíz | H30: 2024-2026
A31: Cecilia_Lopez | B31: =B30+1 -> 1030 | C31: Cecilia López | D31: Cecilia López | E31: Ma. Cecilia López Carrasco | F31: Ma. Cecilia López Carrasco
A32: Carmen_Hernandez | B32: =B31+1 -> 1031 | C32: Cármen Hernández | D32: Cármen Hernández | E32: Ma. del Cármen Hernández Beltrán | F32: Ma. del Cármen Hernández Beltrán
A33: Eloina_Pelaez | B33: =B32+1 -> 1032 | C33: Eloína Peláez | D33: Eloína Peláez | E33: Ma. Eloína Peláez Valdéz | F33: Ma. Eloína Peláez Valdéz
A34: Magdalena_Bayona | B34: =B33+1 -> 1033 | C34: Magdalena Bayona | D34: Magdalena Bayona | E34: Magdalena Bayona N. | F34: Magdalena Bayona N.
A35: Marco_Polo | B35: =B34+1 -> 1034 | C35: Marco Polo | D35: Marco Polo | E35: Marco Antonio Polo Carrillo | F35: Marco Antonio Polo Carrillo
A36: Mariana_Espinosa | B36: =B35+1 -> 1035 | C36: Mariana Espinosa | D36: Mariana Espinosa | E36: Mariana Espinosa Aldama | F36: Mariana Espinosa Aldama | G36: https://mmss.iimas.unam.mx/posdoctorales/dra-mariana-espinosa-aldama/ | H36: 2024-2028
A37: Miguel_Campos | B37: =B36+1 -> 1036 | C37: Miguel Campos | D37: Miguel Campos | E37: Miguel Ángel Campos Hernández | F37: Miguel Ángel Campos Hernández
A38: Miguel_Rossano | B38: =B37+1 -> 1037 | C38: Miguel Rossano | D38: Miguel Rossano | E38: Miguel Ángel Rossano Ávila | F38: Miguel Ángel Rossano Ávila
A39: Narda_Alcantara | B39: =B38+1 -> 1038 | C39: Narda Alcántara | D39: Narda Alcántara | E39: Narda Alcántara Valverde | F39: Narda Alcántara Valverde
A40: Nestor_Paredes | B40: =B39+1 -> 1039 | C40: Néstor Paredes | D40: Néstor Paredes | E40: Néstor Francisco Paredes Urbina | F40: Néstor Francisco Paredes Urbina
A41: Norma_Uribe | B41: =B40+1 -> 1040 | C41: Norma Uribe | D41: Norma Uribe | E41: Norma Elena Uribe Memije | F41: Norma Elena Uribe Memije
A42: Philip_Sinclair | B42: =B41+1 -> 1041 | C42: Philip Sinclair | D42: Philip Sinclair | E42: Philip Andrew Sinclair | F42: Philip Andrew Sinclair
A43: Pilar_Galarza | B43: =B42+1 -> 1042 | C43: Pilar Galarza | D43: Pilar Galarza | E43: Ma. del Pilar Galarza Barrios | F43: Ma. del Pilar Galarza Barrios
A44: Raul_Carbajal | B44: =B43+1 -> 1043 | C44: Raúl Carbajal | D44: Raúl Carbajal | E44: Raúl Carbajal Moreno | F44: Raúl Carbajal Moreno
A45: Ricardo_Lopez | B45: =B44+1 -> 1044 | C45: Ricardo López | D45: Ricardo López | E45: Ricardo López Montes de Oca | F45: Ricardo López Montes de Oca
A46: Sandra_Smith | B46: =B45+1 -> 1045 | C46: Sandra Smith | D46: Sandra Smith | E46: Sandra E. Smith Aguilar | F46: Sandra E. Smith Aguilar
A47: Sara_Medina | B47: =B46+1 -> 1046 | C47: Sara Medina | D47: Sara Medina | E47: Sara Rosa Medina Martínez | F47: Sara Rosa Medina Martínez
A48: Silvia_Casasola | B48: =B47+1 -> 1047 | C48: Silvia Casasola | D48: Silvia Casasola | E48: Silvia Priscila Casasola Vargas | F48: Silvia Priscila Casasola Vargas
... A51: Teresa_de_Leon | B51: =B50+1 -> 1050 | C51: Teresa de León | D51: Teresa de León | E51: Teresa Guadalupe de León Escobedo | F51: Teresa Guadalupe de León Escobedo
B52: =B51+1 -> 1051
B53: =B52+1 -> 1052
B54: =B53+1 -> 1053
B55: =B54+1 -> 1054
B56: =B55+1 -> 1055
...

Sheet cat_attr_class
A1: attr_class_code | B1: attr_class_id | C1: attr_class_title_en | D1: attr_class_title_es
A2: Metodo | B2: 1001 | C2: Methoddology | D2: Metodología
A3: Linea | B3: =B2+1 -> 1002 | C3: Line of research | D3: Línea de investigación
A4: Objeto | B4: =B3+1 -> 1003 | C4: Object of study | D4: Objeto de estudio
A5: Tema | B5: =B4+1 -> 1004 | C5: Subject | D5: Tema
A6: Periodo | B6: =B5+1 -> 1005 | C6: Period | D6: Periodo
A7: Nombramiento | B7: =B6+1 -> 1006 | C7: Title | D7: Nombramiento
B8: =B7+1 -> 1007
B9: =B8+1 -> 1008
B10: =B9+1 -> 1009
B11: =B10+1 -> 1010
B12: =B11+1 -> 1011
B13: =B12+1 -> 1012
B14: =B13+1 -> 1013
B15: =B14+1 -> 1014
B16: =B15+1 -> 1015
B17: =B16+1 -> 1016
B18: =B17+1 -> 1017
B19: =B18+1 -> 1018
... B1001: =B1000+1 -> 2000

Sheet cat_attribute
A1: attribute_label_en | B1: attribute_id | C1: attribute_label_es | D1: attribute_context_class_id | E1: attribute_context_class_code | F1: attribute_attr_class_id | G1: attribute_attr_class_code | H1: attribute_title_en | I1: attribute_title_es | J1: attribute_formula | K1: attribute_explanation_en | L1: attribute_explanation_es | M1: attribute_reference
A2: Agent-Based Model Analysis | B2: 5001 | C2: Analisis de modelos basados en agentes | D2: =VLOOKUP(E2,cat_context_class!$A$2:$B$1001,2,0) -> 5000 | E2: MMSS | F2: =VLOOKUP(G2,cat_attr_class!$A$2:$B$1001,2,0) -> 1001 | G2: Metodo | H2: Agent-Based Model Analysis | I2: Análisis de modelos basados en agentes
A3: Archival Analysis | B3: =B2+1 -> 5002 | C3: Analisis de Archivo | D3: =VLOOKUP(E3,cat_context_class!$A$2:$B$1001,2,0) -> 5000 | E3: MMSS | F3: =VLOOKUP(G3,cat_attr_class!$A$2:$B$1001,2,0) -> 1001 | G3: Metodo | H3: Archival Analysis | I3: Análisis de Archivo
A4: Bibliometrics and Scientometrics | B4: =B3+1 -> 5003 | C4: Bibliometria y cienciometria | D4: =VLOOKUP(E4,cat_context_class!$A$2:$B$1001,2,0) -> 5000 | E4: MMSS | F4: =VLOOKUP(G4,cat_attr_class!$A$2:$B$1001,2,0) -> 1001 | G4: Metodo | H4: Bibliometrics and Scientometrics | I4: Bibliometría y cienciometría
A5: Bioinformatics Tools | B5: =B4+1 -> 5004 | C5: Herramientas bioinformaticas | D5: =VLOOKUP(E5,cat_context_class!$A$2:$B$1001,2,0) -> 5000 | E5: MMSS | F5: =VLOOKUP(G5,cat_attr_class!$A$2:$B$1001,2,0) -> 1001 | G5: Metodo | H5: Bioinformatics Tools | I5: Herramientas bioinformáticas
A6: Cluster Analysis | B6: =B5+1 -> 5005 | C6: Analisis de Conglomerados | D6: =VLOOKUP(E6,cat_context_class!$A$2:$B$1001,2,0) -> 5000 | E6: MMSS | F6: =VLOOKUP(G6,cat_attr_class!$A$2:$B$1001,2,0) -> 1001 | G6: Metodo | H6: Cluster Analysis, k-Means Clustering | I6: Análisis de Conglomerados, Clusterización con k-medias
A7: Computational Qualitative Analysis | B7: =B6+1 -> 5006 | C7: Analisis Cualitativo Computacional | D7: =VLOOKUP(E7,cat_context_class!$A$2:$B$1001,2,0) -> 5000 | E7: MMSS | F7: =VLOOKUP(G7,cat_attr_class!$A$2:$B$1001,2,0) -> 1001 | G7: Metodo | H7: Computational Qualitative Analysis | I7: Análisis Cualitativo Computacional
A8: Correspondence Analysis | B8: =B7+1 -> 5007 | C8: Analisis de Correspondencia | D8: =VLOOKUP(E8,cat_context_class!$A$2:$B$1001,2,0) -> 5000 | E8: MMSS | F8: =VLOOKUP(G8,cat_attr_class!$A$2:$B$1001,2,0) -> 1001 | G8: Metodo | H8: Correspondence Analysis | I8: Análisis de Correspondencia
A9: Digital Source Mining | B9: =B8+1 -> 5008 | C9: Mineria de Fuentes Digitales | D9: =VLOOKUP(E9,cat_context_class!$A$2:$B$1001,2,0) -> 5000 | E9: MMSS | F9: =VLOOKUP(G9,cat_attr_class!$A$2:$B$1001,2,0) -> 1001 | G9: Metodo | H9: Digital Source Mining | I9: Minería de Fuentes Digitales
A10: Direct Observation of Behavior | B10: =B9+1 -> 5009 | C10: Observacion directa | D10: =VLOOKUP(E10,cat_context_class!$A$2:$B$1001,2,0) -> 5000 | E10: MMSS | F10: =VLOOKUP(G10,cat_attr_class!$A$2:$B$1001,2,0) -> 1001 | G10: Metodo | H10: Direct Observation of Behavior | I10: Observación directa del comportamiento
A11: Document Analysis | B11: =B10+1 -> 5010 | C11: Analisis documental | D11: =VLOOKUP(E11,cat_context_class!$A$2:$B$1001,2,0) -> 5000 | E11: MMSS | F11: =VLOOKUP(G11,cat_attr_class!$A$2:$B$1001,2,0) -> 1001 | G11: Metodo | H11: Document Analysis | I11: Análisis Documental
A12: Ethnography | B12: =B11+1 -> 5011 | C12: Etnografia | D12: =VLOOKUP(E12,cat_context_class!$A$2:$B$1001,2,0) -> 5000 | E12: MMSS | F12: =VLOOKUP(G12,cat_attr_class!$A$2:$B$1001,2,0) -> 1001 | G12: Metodo | H12: Ethnography | I12: Etnografía
A13: Formal Concept Analysis | B13: =B12+1 -> 5012 | C13: Analisis de conceptos formales | D13: =VLOOKUP(E13,cat_context_class!$A$2:$B$1001,2,0) -> 5000 | E13: MMSS | F13: =VLOOKUP(G13,cat_attr_class!$A$2:$B$1001,2,0) -> 1001 | G13: Metodo | H13: Formal Concept Analysis | I13: Análisis de Conceptos Formales
A14: Genetic Analysis | B14: =B13+1 -> 5013 | C14: Analisis genetico | D14: =VLOOKUP(E14,cat_context_class!$A$2:$B$1001,2,0) -> 5000 | E14: MMSS | F14: =VLOOKUP(G14,cat_attr_class!$A$2:$B$1001,2,0) -> 1001 | G14: Metodo | H14: Genetic Analysis | I14: Análisis Genético
... A89: Technician | B89: =B88+1 -> 5088 | C89: Tecnicos | D89: =VLOOKUP(E89,cat_context_class!$A$2:$B$1001,2,0) -> 5000 | E89: MMSS | F89: =VLOOKUP(G89,cat_attr_class!$A$2:$B$1001,2,0) -> 1006 | G89: Nombramiento | H89: Technician | I89: Técnicos
B90: =B89+1 -> 5089 | D90: =VLOOKUP(E90,cat_context_class!$A$2:$B$1001,2,0) -> #N/A | F90: =VLOOKUP(G90,cat_attr_class!$A$2:$B$1001,2,0) -> #N/A
B91: =B90+1 -> 5090 | D91: =VLOOKUP(E91,cat_context_class!$A$2:$B$1001,2,0) -> #N/A | F91: =VLOOKUP(G91,cat_attr_class!$A$2:$B$1001,2,0) -> #N/A
B92: =B91+1 -> 5091 | D92: =VLOOKUP(E92,cat_context_class!$A$2:$B$1001,2,0) -> #N/A | F92: =VLOOKUP(G92,cat_attr_class!$A$2:$B$1001,2,0) -> #N/A
B93: =B92+1 -> 5092 | D93: =VLOOKUP(E93,cat_context_class!$A$2:$B$1001,2,0) -> #N/A | F93: =VLOOKUP(G93,cat_attr_class!$A$2:$B$1001,2,0) -> #N/A
B94: =B93+1 -> 5093 | D94: =VLOOKUP(E94,cat_context_class!$A$2:$B$1001,2,0) -> #N/A | F94: =VLOOKUP(G94,cat_attr_class!$A$2:$B$1001,2,0) -> #N/A
B95: =B94+1 -> 5094 | D95: =VLOOKUP(E95,cat_context_class!$A$2:$B$1001,2,0) -> #N/A | F95: =VLOOKUP(G95,cat_attr_class!$A$2:$B$1001,2,0) -> #N/A
B96: =B95+1 -> 5095 | D96: =VLOOKUP(E96,cat_context_class!$A$2:$B$1001,2,0) -> #N/A | F96: =VLOOKUP(G96,cat_attr_class!$A$2:$B$1001,2,0) -> #N/A
B97: =B96+1 -> 5096 | D97: =VLOOKUP(E97,cat_context_class!$A$2:$B$1001,2,0) -> #N/A | F97: =VLOOKUP(G97,cat_attr_class!$A$2:$B$1001,2,0) -> #N/A
B98: =B97+1 -> 5097 | D98: =VLOOKUP(E98,cat_context_class!$A$2:$B$1001,2,0) -> #N/A | F98: =VLOOKUP(G98,cat_attr_class!$A$2:$B$1001,2,0) -> #N/A
B99: =B98+1 -> 5098 | D99: =VLOOKUP(E99,cat_context_class!$A$2:$B$1001,2,0) -> #N/A | F99: =VLOOKUP(G99,cat_attr_class!$A$2:$B$1001,2,0) -> #N/A
B100: =B99+1 -> 5099 | D100: =VLOOKUP(E100,cat_context_class!$A$2:$B$1001,2,0) -> #N/A | F100: =VLOOKUP(G100,cat_attr_class!$A$2:$B$1001,2,0) -> #N/A
B101: =B100+1 -> 5100 | D101: =VLOOKUP(E101,cat_context_class!$A$2:$B$1001,2,0) -> #N/A | F101: =VLOOKUP(G101,cat_attr_class!$A$2:$B$1001,2,0) -> #N/A
... B1001: =B1000+1 -> 6000 | D1001: =VLOOKUP(E1001,cat_context_class!$A$2:$B$1001,2,0) -> #N/A | F1001: =VLOOKUP(G1001,cat_attr_class!$A$2:$B$1001,2,0) -> #N/A

Sheet cat_other
A1: context_values
A2: Pending
A3: 1
A4: 0

Sheet Cat Validation
A1: column | B1: unique | C1: non-empty
A2: object_code | B2: =SUM(IF(ISBLANK(cat_object!A$2:A$1001),"",1/COUNTIF(cat_object!A$2:A$1001,cat_object!A$2:A$1001))) -> 50 | C2: =COUNTIF(cat_object!A$2:A$1001,"<>") -> 50
A3: object_id | B3: {=SUM(IF(ISBLANK(cat_object!B$2:B$1001),"",1/COUNTIF(cat_object!B$2:B$1001,cat_object!B$2:B$1001)))} -> 1000 | C3: =COUNTIF(cat_object!B$2:B$1001,"<>") -> 1000
A4: attribute_label_en | B4: {=SUM(IF(ISBLANK(cat_attribute!A$2:A$1001),"",1/COUNTIF(cat_attribute!A$2:A$1001,cat_attribute!A$2:A$1001)))} -> 88 | C4: =COUNTIF(cat_attribute!A$2:A$1001,"<>") -> 88
A5: attribute_id | B5: {=SUM(IF(ISBLANK(cat_attribute!B$2:B$1001),"",1/COUNTIF(cat_attribute!B$2:B$1001,cat_attribute!B$2:B$1001)))} -> 1000 | C5: =COUNTIF(cat_attribute!B$2:B$1001,"<>") -> 1000
A6: attr_class_code | B6: {=SUM(IF(ISBLANK(cat_attr_class!A$2:A$1001),"",1/COUNTIF(cat_attr_class!A$2:A$1001,cat_attr_class!A$2:A$1001)))} -> 6 | C6: =COUNTIF(cat_attr_class!A$2:A$1001,"<>") -> 6
A7: attr_class_id | B7: {=SUM(IF(ISBLANK(cat_attr_class!B$2:B$1001),"",1/COUNTIF(cat_attr_class!B$2:B$1001,cat_attr_class!B$2:B$1001)))} -> 1000 | C7: =COUNTIF(cat_attr_class!B$2:B$1001,"<>") -> 1000
A8: context_code | B8: {=SUM(IF(ISBLANK(cat_context!A$2:A$1001),"",1/COUNTIF(cat_context!A$2:A$1001,cat_context!A$2:A$1001)))} -> 3 | C8: =COUNTIF(cat_context!A$2:A$1001,"<>") -> 3
A9: context_id | B9: {=SUM(IF(ISBLANK(cat_context!B$2:B$1001),"",1/COUNTIF(cat_context!B$2:B$1001,cat_context!B$2:B$1001)))} -> 1000 | C9: =COUNTIF(cat_context!B$2:B$1001,"<>") -> 1000

Sheet Lineas
A1: Context: | B1: =VLOOKUP($C$1,cat_context!$A$2:$B$1001,2,0) -> 1 | C1: Lineas
J2: Attributes | K2: id | L2: =VLOOKUP(L$11,cat_attribute!$A$2:$M$1001,2,0) -> 5029 | M2: =VLOOKUP(M$11,cat_attribute!$A$2:$M$1001,2,0) -> 5030 | N2: =VLOOKUP(N$11,cat_attribute!$A$2:$M$1001,2,0) -> 5031 | O2: =VLOOKUP(O$11,cat_attribute!$A$2:$M$1001,2,0) -> 5032 | P2: =VLOOKUP(P$11,cat_attribute!$A$2:$M$1001,2,0) -> 5033 | Q2: =VLOOKUP(Q$11,cat_attribute!$A$2:$M$1001,2,0) -> 5034 | R2: =VLOOKUP(R$11,cat_attribute!$A$2:$M$1001,2,0) -> 5035 | S2: =VLOOKUP(S$11,cat_attribute!$A$2:$M$1001,2,0) -> 5036 | ... AP2: =VLOOKUP(AP$11,cat_attribute!$A$2:$M$1001,2,0) -> 5060
K3: reference | L3: =VLOOKUP(L$11,cat_attribute!$A$2:$M$1001,13,0) -> 0 | M3: =VLOOKUP(M$11,cat_attribute!$A$2:$M$1001,13,0) -> 0 | N3: =VLOOKUP(N$11,cat_attribute!$A$2:$M$1001,13,0) -> 0 | O3: =VLOOKUP(O$11,cat_attribute!$A$2:$M$1001,13,0) -> 0 | P3: =VLOOKUP(P$11,cat_attribute!$A$2:$M$1001,13,0) -> 0 | Q3: =VLOOKUP(Q$11,cat_attribute!$A$2:$M$1001,13,0) -> 0 | R3: =VLOOKUP(R$11,cat_attribute!$A$2:$M$1001,13,0) -> 0 | S3: =VLOOKUP(S$11,cat_attribute!$A$2:$M$1001,13,0) -> 0 | ... AP3: =VLOOKUP(AP$11,cat_attribute!$A$2:$M$1001,13,0) -> 0
K4: explanation_es | L4: =VLOOKUP(L$11,cat_attribute!$A$2:$M$1001,12,0) -> 0 | M4: =VLOOKUP(M$11,cat_attribute!$A$2:$M$1001,12,0) -> 0 | N4: =VLOOKUP(N$11,cat_attribute!$A$2:$M$1001,12,0) -> 0 | O4: =VLOOKUP(O$11,cat_attribute!$A$2:$M$1001,12,0) -> 0 | P4: =VLOOKUP(P$11,cat_attribute!$A$2:$M$1001,12,0) -> 0 | Q4: =VLOOKUP(Q$11,cat_attribute!$A$2:$M$1001,12,0) -> 0 | R4: =VLOOKUP(R$11,cat_attribute!$A$2:$M$1001,12,0) -> 0 | S4: =VLOOKUP(S$11,cat_attribute!$A$2:$M$1001,12,0) -> 0 | ... AP4: =VLOOKUP(AP$11,cat_attribute!$A$2:$M$1001,12,0) -> 0
K5: explanation_en | L5: =VLOOKUP(L$11,cat_attribute!$A$2:$M$1001,11,0) -> 0 | M5: =VLOOKUP(M$11,cat_attribute!$A$2:$M$1001,11,0) -> 0 | N5: =VLOOKUP(N$11,cat_attribute!$A$2:$M$1001,11,0) -> 0 | O5: =VLOOKUP(O$11,cat_attribute!$A$2:$M$1001,11,0) -> 0 | P5: =VLOOKUP(P$11,cat_attribute!$A$2:$M$1001,11,0) -> 0 | Q5: =VLOOKUP(Q$11,cat_attribute!$A$2:$M$1001,11,0) -> 0 | R5: =VLOOKUP(R$11,cat_attribute!$A$2:$M$1001,11,0) -> 0 | S5: =VLOOKUP(S$11,cat_attribute!$A$2:$M$1001,11,0) -> 0 | ... AP5: =VLOOKUP(AP$11,cat_attribute!$A$2:$M$1001,11,0) -> 0
K6: formula | L6: =VLOOKUP(L$11,cat_attribute!$A$2:$M$1001,10,0) -> 0 | M6: =VLOOKUP(M$11,cat_attribute!$A$2:$M$1001,10,0) -> 0 | N6: =VLOOKUP(N$11,cat_attribute!$A$2:$M$1001,10,0) -> 0 | O6: =VLOOKUP(O$11,cat_attribute!$A$2:$M$1001,10,0) -> 0 | P6: =VLOOKUP(P$11,cat_attribute!$A$2:$M$1001,10,0) -> 0 | Q6: =VLOOKUP(Q$11,cat_attribute!$A$2:$M$1001,10,0) -> 0 | R6: =VLOOKUP(R$11,cat_attribute!$A$2:$M$1001,10,0) -> 0 | S6: =VLOOKUP(S$11,cat_attribute!$A$2:$M$1001,10,0) -> 0 | ... AP6: =VLOOKUP(AP$11,cat_attribute!$A$2:$M$1001,10,0) -> 0
K7: title_es | L7: =VLOOKUP(L$11,cat_attribute!$A$2:$M$1001,9,0) -> Redes académicas | M7: =VLOOKUP(M$11,cat_attribute!$A$2:$M$1001,9,0) -> Indicadores de CyT | N7: =VLOOKUP(N$11,cat_attribute!$A$2:$M$1001,9,0) -> Cambio ambiental y climático | O7: =VLOOKUP(O$11,cat_attribute!$A$2:$M$1001,9,0) -> Procesamiento colectivo de información | P7: =VLOOKUP(P$11,cat_attribute!$A$2:$M$1001,9,0) -> Sistemas Sociales Complejos y Dinámicas Sociales | Q7: =VLOOKUP(Q$11,cat_attribute!$A$2:$M$1001,9,0) -> Análisis Computacional | R7: =VLOOKUP(R$11,cat_attribute!$A$2:$M$1001,9,0) -> Pensamiento Computacional | S7: =VLOOKUP(S$11,cat_attribute!$A$2:$M$1001,9,0) -> Estudios de Género | ... AP7: =VLOOKUP(AP$11,cat_attribute!$A$2:$M$1001,9,0) -> Resilencia
K8: title_en | L8: =VLOOKUP(L$11,cat_attribute!$A$2:$M$1001,8,0) -> Academic networks | M8: =VLOOKUP(M$11,cat_attribute!$A$2:$M$1001,8,0) -> CT indicators | N8: =VLOOKUP(N$11,cat_attribute!$A$2:$M$1001,8,0) -> Enviromental and Climate change | O8: =VLOOKUP(O$11,cat_attribute!$A$2:$M$1001,8,0) -> Collective processing of information | P8: =VLOOKUP(P$11,cat_attribute!$A$2:$M$1001,8,0) -> Complex social systems | Q8: =VLOOKUP(Q$11,cat_attribute!$A$2:$M$1001,8,0) -> Computational analysis | R8: =VLOOKUP(R$11,cat_attribute!$A$2:$M$1001,8,0) -> Computational Thinking | S8: =VLOOKUP(S$11,cat_attribute!$A$2:$M$1001,8,0) -> Gender studies | ... AP8: =VLOOKUP(AP$11,cat_attribute!$A$2:$M$1001,8,0) -> Resilience
K9: class_code | L9: =VLOOKUP(L$11,cat_attribute!$A$2:$M$1001,7,0) -> Linea | M9: =VLOOKUP(M$11,cat_attribute!$A$2:$M$1001,7,0) -> Linea | N9: =VLOOKUP(N$11,cat_attribute!$A$2:$M$1001,7,0) -> Linea | O9: =VLOOKUP(O$11,cat_attribute!$A$2:$M$1001,7,0) -> Linea | P9: =VLOOKUP(P$11,cat_attribute!$A$2:$M$1001,7,0) -> Linea | Q9: =VLOOKUP(Q$11,cat_attribute!$A$2:$M$1001,7,0) -> Metodo | R9: =VLOOKUP(R$11,cat_attribute!$A$2:$M$1001,7,0) -> Linea | S9: =VLOOKUP(S$11,cat_attribute!$A$2:$M$1001,7,0) -> Linea | ... AP9: =VLOOKUP(AP$11,cat_attribute!$A$2:$M$1001,7,0) -> Linea
D10: Objects | K10: label_es | L10: =VLOOKUP(L$11,cat_attribute!$A$2:$M$1001,3,0) -> Redes academicas | M10: =VLOOKUP(M$11,cat_attribute!$A$2:$M$1001,3,0) -> Indicadores de CyT | N10: =VLOOKUP(N$11,cat_attribute!$A$2:$M$1001,3,0) -> Cambio ambiental y climatico | O10: =VLOOKUP(O$11,cat_attribute!$A$2:$M$1001,3,0) -> Procesamiento colectivo de informacion | P10: =VLOOKUP(P$11,cat_attribute!$A$2:$M$1001,3,0) -> Sistemas Sociales Complejos y Dinámicas Sociales | Q10: =VLOOKUP(Q$11,cat_attribute!$A$2:$M$1001,3,0) -> Analisis Computacional | R10: =VLOOKUP(R$11,cat_attribute!$A$2:$M$1001,3,0) -> Pensamiento Computacional | S10: =VLOOKUP(S$11,cat_attribute!$A$2:$M$1001,3,0) -> Estudios de Genero | ... AP10: =VLOOKUP(AP$11,cat_attribute!$A$2:$M$1001,3,0) -> Resilencia
D11: id | E11: reference | F11: year | G11: desc_es | H11: desc_en | I11: label_es | J11: label_en | K11: code label_en | L11: Academic networks | M11: CT indicators | N11: Enviromental and Climate change | O11: Collective processing of information | P11: Complex social systems | Q11: Computational analysis | R11: Computational Thinking | S11: Gender studies | T11: Academic entities | U11: General theory of social systems | V11: Geographies of Science | W11: History of Knowledge Circulation | X11: History of Probability | Y11: History of Statistics | Z11: Institutionalization of Statistics | AA11: Maps of science | AB11: Mathematical modeling | AC11: Quantitative History | AD11: Reproduction of Academic Spaces | AE11: Social Behavior | AF11: Social Categories and Classifications | AG11: Social Complexity | AH11: Social frontiers | AI11: Social studies of CTS | AJ11: Socio-ecology | AK11: Socio-history of quantification | AL11: Sociology of Professions | AM11: Structural epistemology of knowledge | AN11: Study of News | AO11: University’s sociocultural history | AP11: Resilience
D12: =VLOOKUP($K12,cat_object!$A$2:$H$1005,2,0) -> 1001 | E12: =VLOOKUP($K12,cat_object!$A$2:$H$1005,7,0) -> 0 | F12: =VLOOKUP($K12,cat_object!$A$2:$H$1005,8,0) -> 0 | G12: =VLOOKUP($K12,cat_object!$A$2:$H$1005,6,0) -> Alejandro Arnulfo Ruiz León | H12: =VLOOKUP($K12,cat_object!$A$2:$H$1005,5,0) -> Alejandro Arnulfo Ruiz León | I12: =VLOOKUP($K12,cat_object!$A$2:$H$1005,4,0) -> Alejandro Ruiz | J12: =VLOOKUP($K12,cat_object!$A$2:$H$1005,3,0) -> Alejandro Ruiz | K12: Alejandro_Ruiz | L12: 1 | M12: 1 | N12: 0 | O12: 0 | P12: 0 | Q12: 1 | R12: 0 | S12: 0 | T12: 0 | U12: 0 | V12: 0 | W12: 0 | X12: 0 | Y12: 0 | Z12: 0 | AA12: 1 | AB12: 1 | AC12: 0 | AD12: 0 | AE12: 0 | AF12: 0 | AG12: 0 | AH12: 0 | AI12: 1 | AJ12: 0 | AK12: 0 | AL12: 0 | AM12: 0 | AN12: 0 | AO12: 0 | AP12: 0
D13: =VLOOKUP($K13,cat_object!$A$2:$H$1005,2,0) -> 1002 | E13: =VLOOKUP($K13,cat_object!$A$2:$H$1005,7,0) -> 0 | F13: =VLOOKUP($K13,cat_object!$A$2:$H$1005,8,0) -> 0 | G13: =VLOOKUP($K13,cat_object!$A$2:$H$1005,6,0) -> Aline Amor Saldaña Sánchez | H13: =VLOOKUP($K13,cat_object!$A$2:$H$1005,5,0) -> Aline Amor Saldaña Sánchez | I13: =VLOOKUP($K13,cat_object!$A$2:$H$1005,4,0) -> Aline Saldaña | J13: =VLOOKUP($K13,cat_object!$A$2:$H$1005,3,0) -> Aline Saldaña | K13: Aline_Saldaña | L13: 0 | M13: 0 | N13: 0 | O13: 0 | P13: 1 | Q13: 0 | R13: 0 | S13: 0 | T13: 0 | U13: 0 | V13: 0 | W13: 0 | X13: 0 | Y13: 0 | Z13: 0 | AA13: 0 | AB13: 0 | AC13: 0 | AD13: 0 | AE13: 1 | AF13: 0 | AG13: 1 | AH13: 0 | AI13: 0 | AJ13: 0 | AK13: 0 | AL13: 0 | AM13: 0 | AN13: 0 | AO13: 0 | AP13: 1
D14: =VLOOKUP($K14,cat_object!$A$2:$H$1005,2,0) -> 1003 | E14: =VLOOKUP($K14,cat_object!$A$2:$H$1005,7,0) -> 0 | F14: =VLOOKUP($K14,cat_object!$A$2:$H$1005,8,0) -> 0 | G14: =VLOOKUP($K14,cat_object!$A$2:$H$1005,6,0) -> Ana María Medeles Hernández | H14: =VLOOKUP($K14,cat_object!$A$2:$H$1005,5,0) -> Ana María Medeles Hernández | I14: =VLOOKUP($K14,cat_object!$A$2:$H$1005,4,0) -> Ana Medeles | J14: =VLOOKUP($K14,cat_object!$A$2:$H$1005,3,0) -> Ana Medeles | K14: Ana_Medeles | L14: 0 | M14: 0 | N14: 0 | O14: 0 | P14: 0 | Q14: 0 | R14: 0 | S14: 0 | T14: 0 | U14: 0 | V14: 0 | W14: 0 | X14: 0 | Y14: 0 | Z14: 1 | AA14: 0 | AB14: 0 | AC14: 0 | AD14: 0 | AE14: 0 | AF14: 1 | AG14: 0 | AH14: 0 | AI14: 1 | AJ14: 0 | AK14: 1 | AL14: 0 | AM14: 0 | AN14: 0 | AO14: 0 | AP14: 0
D15: =VLOOKUP($K15,cat_object!$A$2:$H$1005,2,0) -> 1004 | E15: =VLOOKUP($K15,cat_object!$A$2:$H$1005,7,0) -> 0 | F15: =VLOOKUP($K15,cat_object!$A$2:$H$1005,8,0) -> 0 | G15: =VLOOKUP($K15,cat_object!$A$2:$H$1005,6,0) -> Carlos Rodríguez Contreras | H15: =VLOOKUP($K15,cat_object!$A$2:$H$1005,5,0) -> Carlos Rodríguez Contreras | I15: =VLOOKUP($K15,cat_object!$A$2:$H$1005,4,0) -> Carlos Rodriguez | J15: =VLOOKUP($K15,cat_object!$A$2:$H$1005,3,0) -> Carlos Rodriguez | K15: Carlos_Rodriguez | L15: 0 | M15: 0 | N15: 0 | O15: 0 | P15: 0 | Q15: 1 | R15: 0 | S15: 0 | T15: 0 | U15: 0 | V15: 0 | W15: 0 | X15: 0 | Y15: 0 | Z15: 0 | AA15: 0 | AB15: 1 | AC15: 0 | AD15: 0 | AE15: 0 | AF15: 0 | AG15: 0 | AH15: 0 | AI15: 0 | AJ15: 0 | AK15: 0 | AL15: 0 | AM15: 0 | AN15: 1 | AO15: 0 | AP15: 0
D16: =VLOOKUP($K16,cat_object!$A$2:$H$1005,2,0) -> 1005 | E16: =VLOOKUP($K16,cat_object!$A$2:$H$1005,7,0) -> 0 | F16: =VLOOKUP($K16,cat_object!$A$2:$H$1005,8,0) -> 0 | G16: =VLOOKUP($K16,cat_object!$A$2:$H$1005,6,0) -> Cristina Jasso del Toro | H16: =VLOOKUP($K16,cat_object!$A$2:$H$1005,5,0) -> Cristina Jasso del Toro | I16: =VLOOKUP($K16,cat_object!$A$2:$H$1005,4,0) -> Cristina Jasso | J16: =VLOOKUP($K16,cat_object!$A$2:$H$1005,3,0) -> Cristina Jasso | K16: Cristina_Jasso | L16: 0 | M16: 0 | N16: 0 | O16: 0 | P16: 1 | Q16: 0 | R16: 0 | S16: 0 | T16: 0 | U16: 0 | V16: 0 | W16: 0 | X16: 0 | Y16: 0 | Z16: 0 | AA16: 0 | AB16: 0 | AC16: 0 | AD16: 0 | AE16: 1 | AF16: 0 | AG16: 1 | AH16: 0 | AI16: 0 | AJ16: 1 | AK16: 0 | AL16: 0 | AM16: 0 | AN16: 0 | AO16: 0 | AP16: 0
D17: =VLOOKUP($K17,cat_object!$A$2:$H$1005,2,0) -> 1011 | E17: =VLOOKUP($K17,cat_object!$A$2:$H$1005,7,0) -> 0 | F17: =VLOOKUP($K17,cat_object!$A$2:$H$1005,8,0) -> 0 | G17: =VLOOKUP($K17,cat_object!$A$2:$H$1005,6,0) -> Gabriela Elisa Sued | H17: =VLOOKUP($K17,cat_object!$A$2:$H$1005,5,0) -> Gabriela Elisa Sued | I17: =VLOOKUP($K17,cat_object!$A$2:$H$1005,4,0) -> Gabriela Sued | J17: =VLOOKUP($K17,cat_object!$A$2:$H$1005,3,0) -> Gabriela Sued | K17: Gabriela_Sued | L17: 0 | M17: 0 | N17: 0 | O17: 1 | P17: 0 | Q17: 1 | R17: 0 | S17: 1 | T17: 0 | U17: 0 | V17: 0 | W17: 0 | X17: 0 | Y17: 0 | Z17: 0 | AA17: 0 | AB17: 1 | AC17: 0 | AD17: 0 | AE17: 0 | AF17: 0 | AG17: 0 | AH17: 0 | AI17: 1 | AJ17: 0 | AK17: 0 | AL17: 0 | AM17: 0 | AN17: 0 | AO17: 0 | AP17: 0
D18: =VLOOKUP($K18,cat_object!$A$2:$H$1005,2,0) -> 1010 | E18: =VLOOKUP($K18,cat_object!$A$2:$H$1005,7,0) -> 0 | F18: =VLOOKUP($K18,cat_object!$A$2:$H$1005,8,0) -> 0 | G18: =VLOOKUP($K18,cat_object!$A$2:$H$1005,6,0) -> Gabriel Ramos Fernández | H18: =VLOOKUP($K18,cat_object!$A$2:$H$1005,5,0) -> Gabriel Ramos Fernández | I18: =VLOOKUP($K18,cat_object!$A$2:$H$1005,4,0) -> Gabriel Ramos | J18: =VLOOKUP($K18,cat_object!$A$2:$H$1005,3,0) -> Gabriel Ramos | K18: Gabriel_Ramos | L18: 0 | M18: 0 | N18: 0 | O18: 1 | P18: 1 | Q18: 0 | R18: 0 | S18: 0 | T18: 0 | U18: 0 | V18: 0 | W18: 0 | X18: 0 | Y18: 0 | Z18: 0 | AA18: 0 | AB18: 0 | AC18: 0 | AD18: 0 | AE18: 0 | AF18: 0 | AG18: 1 | AH18: 0 | AI18: 0 | AJ18: 0 | AK18: 0 | AL18: 0 | AM18: 0 | AN18: 0 | AO18: 0 | AP18: 0
D19: =VLOOKUP($K19,cat_object!$A$2:$H$1005,2,0) -> 1015 | E19: =VLOOKUP($K19,cat_object!$A$2:$H$1005,7,0) -> 0 | F19: =VLOOKUP($K19,cat_object!$A$2:$H$1005,8,0) -> 0 | G19: =VLOOKUP($K19,cat_object!$A$2:$H$1005,6,0) -> Israel García Solares | H19: =VLOOKUP($K19,cat_object!$A$2:$H$1005,5,0) -> Israel García Solares | I19: =VLOOKUP($K19,cat_object!$A$2:$H$1005,4,0) -> Israel García | J19: =VLOOKUP($K19,cat_object!$A$2:$H$1005,3,0) -> Israel García | K19: Israel_Garcia | L19: 0 | M19: 0 | N19: 0 | O19: 0 | P19: 0 | Q19: 0 | R19: 0 | S19: 0 | T19: 0 | U19: 0 | V19: 0 | W19: 0 | X19: 0 | Y19: 0 | Z19: 0 | AA19: 0 | AB19: 0 | AC19: 1 | AD19: 0 | AE19: 0 | AF19: 0 | AG19: 0 | AH19: 0 | AI19: 0 | AJ19: 0 | AK19: 1 | AL19: 0 | AM19: 0 | AN19: 0 | AO19: 1 | AP19: 0
D20: =VLOOKUP($K20,cat_object!$A$2:$H$1005,2,0) -> 1016 | E20: =VLOOKUP($K20,cat_object!$A$2:$H$1005,7,0) -> 0 | F20: =VLOOKUP($K20,cat_object!$A$2:$H$1005,8,0) -> 0 | G20: =VLOOKUP($K20,cat_object!$A$2:$H$1005,6,0) -> Israel Sandoval Grajeda | H20: =VLOOKUP($K20,cat_object!$A$2:$H$1005,5,0) -> Israel Sandoval Grajeda | I20: =VLOOKUP($K20,cat_object!$A$2:$H$1005,4,0) -> Israel Sandoval | J20: =VLOOKUP($K20,cat_object!$A$2:$H$1005,3,0) -> Israel Sandoval | K20: Israel_Sandoval | L20: 0 | M20: 1 | N20: 0 | O20: 0 | P20: 0 | Q20: 0 | R20: 1 | S20: 0 | T20: 1 | U20: 0 | V20: 0 | W20: 0 | X20: 0 | Y20: 0 | Z20: 0 | AA20: 0 | AB20: 0 | AC20: 0 | AD20: 0 | AE20: 0 | AF20: 0 | AG20: 0 | AH20: 0 | AI20: 0 | AJ20: 0 | AK20: 0 | AL20: 0 | AM20: 0 | AN20: 0 | AO20: 1 | AP20: 0
D21: =VLOOKUP($K21,cat_object!$A$2:$H$1005,2,0) -> 1022 | E21: =VLOOKUP($K21,cat_object!$A$2:$H$1005,7,0) -> 0 | F21: =VLOOKUP($K21,cat_object!$A$2:$H$1005,8,0) -> 0 | G21: =VLOOKUP($K21,cat_object!$A$2:$H$1005,6,0) -> José Gerardo López Bonifacio | H21: =VLOOKUP($K21,cat_object!$A$2:$H$1005,5,0) -> José Gerardo López Bonifacio | I21: =VLOOKUP($K21,cat_object!$A$2:$H$1005,4,0) -> Gerardo López | J21: =VLOOKUP($K21,cat_object!$A$2:$H$1005,3,0) -> Gerardo López | K21: Gerardo_Lopez | L21: 0 | M21: 0 | N21: 0 | O21: 0 | P21: 1 | Q21: 0 | R21: 0 | S21: 0 | T21: 0 | U21: 0 | V21: 0 | W21: 0 | X21: 0 | Y21: 0 | Z21: 0 | AA21: 0 | AB21: 0 | AC21: 0 | AD21: 0 | AE21: 0 | AF21: 0 | AG21: 1 | AH21: 0 | AI21: 0 | AJ21: 0 | AK21: 0 | AL21: 0 | AM21: 0 | AN21: 0 | AO21: 0 | AP21: 0
D22: =VLOOKUP($K22,cat_object!$A$2:$H$1005,2,0) -> 1029 | E22: =VLOOKUP($K22,cat_object!$A$2:$H$1005,7,0) -> 0 | F22: =VLOOKUP($K22,cat_object!$A$2:$H$1005,8,0) -> 2024-2026 | G22: =VLOOKUP($K22,cat_object!$A$2:$H$1005,6,0) -> Liliana Ramírez Ruíz | H22: =VLOOKUP($K22,cat_object!$A$2:$H$1005,5,0) -> Liliana Ramírez Ruíz | I22: =VLOOKUP($K22,cat_object!$A$2:$H$1005,4,0) -> Liliana Ramírez | J22: =VLOOKUP($K22,cat_object!$A$2:$H$1005,3,0) -> Liliana Ramírez | K22: Liliana_Ramirez | L22: 0 | M22: 0 | N22: 0 | O22: 0 | P22: 0 | Q22: 0 | R22: 0 | S22: 1 | T22: 0 | U22: 1 | V22: 0 | W22: 0 | X22: 0 | Y22: 0 | Z22: 0 | AA22: 0 | AB22: 0 | AC22: 0 | AD22: 0 | AE22: 0 | AF22: 0 | AG22: 0 | AH22: 0 | AI22: 0 | AJ22: 0 | AK22: 0 | AL22: 0 | AM22: 0 | AN22: 0 | AO22: 0 | AP22: 0
D23: =VLOOKUP($K23,cat_object!$A$2:$H$1005,2,0) -> 1035 | E23: =VLOOKUP($K23,cat_object!$A$2:$H$1005,7,0) -> https://mmss.iimas.unam.mx/posdoctorales/dra-mariana-espinosa-aldama/ | F23: =VLOOKUP($K23,cat_object!$A$2:$H$1005,8,0) -> 2024-2028 | G23: =VLOOKUP($K23,cat_object!$A$2:$H$1005,6,0) -> Mariana Espinosa Aldama | H23: =VLOOKUP($K23,cat_object!$A$2:$H$1005,5,0) -> Mariana Espinosa Aldama | I23: =VLOOKUP($K23,cat_object!$A$2:$H$1005,4,0) -> Mariana Espinosa | J23: =VLOOKUP($K23,cat_object!$A$2:$H$1005,3,0) -> Mariana Espinosa | K23: Mariana_Espinosa | L23: 0 | M23: 0 | N23: 0 | O23: 0 | P23: 0 | Q23: 1 | R23: 0 | S23: 0 | T23: 0 | U23: 0 | V23: 0 | W23: 0 | X23: 0 | Y23: 0 | Z23: 0 | AA23: 1 | AB23: 0 | AC23: 0 | AD23: 0 | AE23: 0 | AF23: 0 | AG23: 0 | AH23: 0 | AI23: 1 | AJ23: 0 | AK23: 0 | AL23: 0 | AM23: 1 | AN23: 0 | AO23: 0 | AP23: 0
... D31: =VLOOKUP($K31,cat_object!$A$2:$H$1005,2,0) -> 1023 | E31: =VLOOKUP($K31,cat_object!$A$2:$H$1005,7,0) -> 0 | F31: =VLOOKUP($K31,cat_object!$A$2:$H$1005,8,0) -> 0 | G31: =VLOOKUP($K31,cat_object!$A$2:$H$1005,6,0) -> Juan Carlos Escalante Leal | H31: =VLOOKUP($K31,cat_object!$A$2:$H$1005,5,0) -> Juan Carlos Escalante Leal | I31: =VLOOKUP($K31,cat_object!$A$2:$H$1005,4,0) -> Juan Escalante | J31: =VLOOKUP($K31,cat_object!$A$2:$H$1005,3,0) -> Juan Escalante | K31: Juan_Escalante | L31: 1 | M31: 0 | N31: 0 | O31: 0 | P31: 0 | Q31: 0 | R31: 0 | S31: 0 | T31: 0 | U31: 0 | V31: 0 | W31: 0 | X31: 0 | Y31: 0 | Z31: 0 | AA31: 0 | AB31: 0 | AC31: 0 | AD31: 0 | AE31: 0 | AF31: 0 | AG31: 0 | AH31: 0 | AI31: 0 | AJ31: 0 | AK31: 0 | AL31: 0 | AM31: 0 | AN31: 0 | AO31: 0 | AP31: 0

Sheet Metodos
A1: Context: | B1: =VLOOKUP($C$1,cat_context!$A$2:$B$1001,2,0) -> 2 | C1: Metodos
J2: Attributes | K2: id | L2: =VLOOKUP(L$11,cat_attribute!$A$2:$M$1001,2,0) -> 5001 | M2: =VLOOKUP(M$11,cat_attribute!$A$2:$M$1001,2,0) -> 5002 | N2: =VLOOKUP(N$11,cat_attribute!$A$2:$M$1001,2,0) -> 5003 | O2: =VLOOKUP(O$11,cat_attribute!$A$2:$M$1001,2,0) -> 5004 | P2: =VLOOKUP(P$11,cat_attribute!$A$2:$M$1001,2,0) -> 5005 | Q2: =VLOOKUP(Q$11,cat_attribute!$A$2:$M$1001,2,0) -> 5006 | R2: =VLOOKUP(R$11,cat_attribute!$A$2:$M$1001,2,0) -> 5007 | S2: =VLOOKUP(S$11,cat_attribute!$A$2:$M$1001,2,0) -> 5008 | ... AM2: =VLOOKUP(AM$11,cat_attribute!$A$2:$M$1001,2,0) -> 5028
K3: reference | L3: =VLOOKUP(L$11,cat_attribute!$A$2:$M$1001,13,0) -> 0 | M3: =VLOOKUP(M$11,cat_attribute!$A$2:$M$1001,13,0) -> 0 | N3: =VLOOKUP(N$11,cat_attribute!$A$2:$M$1001,13,0) -> 0 | O3: =VLOOKUP(O$11,cat_attribute!$A$2:$M$1001,13,0) -> 0 | P3: =VLOOKUP(P$11,cat_attribute!$A$2:$M$1001,13,0) -> 0 | Q3: =VLOOKUP(Q$11,cat_attribute!$A$2:$M$1001,13,0) -> 0 | R3: =VLOOKUP(R$11,cat_attribute!$A$2:$M$1001,13,0) -> 0 | S3: =VLOOKUP(S$11,cat_attribute!$A$2:$M$1001,13,0) -> 0 | ... AM3: =VLOOKUP(AM$11,cat_attribute!$A$2:$M$1001,13,0) -> 0
K4: explanation_es | L4: =VLOOKUP(L$11,cat_attribute!$A$2:$M$1001,12,0) -> 0 | M4: =VLOOKUP(M$11,cat_attribute!$A$2:$M$1001,12,0) -> 0 | N4: =VLOOKUP(N$11,cat_attribute!$A$2:$M$1001,12,0) -> 0 | O4: =VLOOKUP(O$11,cat_attribute!$A$2:$M$1001,12,0) -> 0 | P4: =VLOOKUP(P$11,cat_attribute!$A$2:$M$1001,12,0) -> 0 | Q4: =VLOOKUP(Q$11,cat_attribute!$A$2:$M$1001,12,0) -> 0 | R4: =VLOOKUP(R$11,cat_attribute!$A$2:$M$1001,12,0) -> 0 | S4: =VLOOKUP(S$11,cat_attribute!$A$2:$M$1001,12,0) -> 0 | ... AM4: =VLOOKUP(AM$11,cat_attribute!$A$2:$M$1001,12,0) -> 0
K5: explanation_en | L5: =VLOOKUP(L$11,cat_attribute!$A$2:$M$1001,11,0) -> 0 | M5: =VLOOKUP(M$11,cat_attribute!$A$2:$M$1001,11,0) -> 0 | N5: =VLOOKUP(N$11,cat_attribute!$A$2:$M$1001,11,0) -> 0 | O5: =VLOOKUP(O$11,cat_attribute!$A$2:$M$1001,11,0) -> 0 | P5: =VLOOKUP(P$11,cat_attribute!$A$2:$M$1001,11,0) -> 0 | Q5: =VLOOKUP(Q$11,cat_attribute!$A$2:$M$1001,11,0) -> 0 | R5: =VLOOKUP(R$11,cat_attribute!$A$2:$M$1001,11,0) -> 0 | S5: =VLOOKUP(S$11,cat_attribute!$A$2:$M$1001,11,0) -> 0 | ... AM5: =VLOOKUP(AM$11,cat_attribute!$A$2:$M$1001,11,0) -> 0
K6: formula | L6: =VLOOKUP(L$11,cat_attribute!$A$2:$M$1001,10,0) -> 0 | M6: =VLOOKUP(M$11,cat_attribute!$A$2:$M$1001,10,0) -> 0 | N6: =VLOOKUP(N$11,cat_attribute!$A$2:$M$1001,10,0) -> 0 | O6: =VLOOKUP(O$11,cat_attribute!$A$2:$M$1001,10,0) -> 0 | P6: =VLOOKUP(P$11,cat_attribute!$A$2:$M$1001,10,0) -> 0 | Q6: =VLOOKUP(Q$11,cat_attribute!$A$2:$M$1001,10,0) -> 0 | R6: =VLOOKUP(R$11,cat_attribute!$A$2:$M$1001,10,0) -> 0 | S6: =VLOOKUP(S$11,cat_attribute!$A$2:$M$1001,10,0) -> 0 | ... AM6: =VLOOKUP(AM$11,cat_attribute!$A$2:$M$1001,10,0) -> 0
K7: title_es | L7: =VLOOKUP(L$11,cat_attribute!$A$2:$M$1001,9,0) -> Análisis de modelos basados en agentes | M7: =VLOOKUP(M$11,cat_attribute!$A$2:$M$1001,9,0) -> Análisis de Archivo | N7: =VLOOKUP(N$11,cat_attribute!$A$2:$M$1001,9,0) -> Bibliometría y cienciometría | O7: =VLOOKUP(O$11,cat_attribute!$A$2:$M$1001,9,0) -> Herramientas bioinformáticas | P7: =VLOOKUP(P$11,cat_attribute!$A$2:$M$1001,9,0) -> Análisis de Conglomerados, Clusterización con k-medias | Q7: =VLOOKUP(Q$11,cat_attribute!$A$2:$M$1001,9,0) -> Análisis Cualitativo Computacional | R7: =VLOOKUP(R$11,cat_attribute!$A$2:$M$1001,9,0) -> Análisis de Correspondencia | S7: =VLOOKUP(S$11,cat_attribute!$A$2:$M$1001,9,0) -> Minería de Fuentes Digitales | ... AM7: =VLOOKUP(AM$11,cat_attribute!$A$2:$M$1001,9,0) -> Análisis de Modelos temáticos
K8: title_en | L8: =VLOOKUP(L$11,cat_attribute!$A$2:$M$1001,8,0) -> Agent-Based Model Analysis | M8: =VLOOKUP(M$11,cat_attribute!$A$2:$M$1001,8,0) -> Archival Analysis | N8: =VLOOKUP(N$11,cat_attribute!$A$2:$M$1001,8,0) -> Bibliometrics and Scientometrics | O8: =VLOOKUP(O$11,cat_attribute!$A$2:$M$1001,8,0) -> Bioinformatics Tools | P8: =VLOOKUP(P$11,cat_attribute!$A$2:$M$1001,8,0) -> Cluster Analysis, k-Means Clustering | Q8: =VLOOKUP(Q$11,cat_attribute!$A$2:$M$1001,8,0) -> Computational Qualitative Analysis | R8: =VLOOKUP(R$11,cat_attribute!$A$2:$M$1001,8,0) -> Correspondence Analysis | S8: =VLOOKUP(S$11,cat_attribute!$A$2:$M$1001,8,0) -> Digital Source Mining | ... AM8: =VLOOKUP(AM$11,cat_attribute!$A$2:$M$1001,8,0) -> Topic Modeling Analysis
K9: class_code | L9: =VLOOKUP(L$11,cat_attribute!$A$2:$M$1001,7,0) -> Metodo | M9: =VLOOKUP(M$11,cat_attribute!$A$2:$M$1001,7,0) -> Metodo | N9: =VLOOKUP(N$11,cat_attribute!$A$2:$M$1001,7,0) -> Metodo | O9: =VLOOKUP(O$11,cat_attribute!$A$2:$M$1001,7,0) -> Metodo | P9: =VLOOKUP(P$11,cat_attribute!$A$2:$M$1001,7,0) -> Metodo | Q9: =VLOOKUP(Q$11,cat_attribute!$A$2:$M$1001,7,0) -> Metodo | R9: =VLOOKUP(R$11,cat_attribute!$A$2:$M$1001,7,0) -> Metodo | S9: =VLOOKUP(S$11,cat_attribute!$A$2:$M$1001,7,0) -> Metodo | ... AM9: =VLOOKUP(AM$11,cat_attribute!$A$2:$M$1001,7,0) -> Metodo
D10: Objects | K10: label_es | L10: =VLOOKUP(L$11,cat_attribute!$A$2:$M$1001,3,0) -> Analisis de modelos basados en agentes | M10: =VLOOKUP(M$11,cat_attribute!$A$2:$M$1001,3,0) -> Analisis de Archivo | N10: =VLOOKUP(N$11,cat_attribute!$A$2:$M$1001,3,0) -> Bibliometria y cienciometria | O10: =VLOOKUP(O$11,cat_attribute!$A$2:$M$1001,3,0) -> Herramientas bioinformaticas | P10: =VLOOKUP(P$11,cat_attribute!$A$2:$M$1001,3,0) -> Analisis de Conglomerados | Q10: =VLOOKUP(Q$11,cat_attribute!$A$2:$M$1001,3,0) -> Analisis Cualitativo Computacional | R10: =VLOOKUP(R$11,cat_attribute!$A$2:$M$1001,3,0) -> Analisis de Correspondencia | S10: =VLOOKUP(S$11,cat_attribute!$A$2:$M$1001,3,0) -> Mineria de Fuentes Digitales | ... AM10: =VLOOKUP(AM$11,cat_attribute!$A$2:$M$1001,3,0) -> Analisis de Modelos tematicos
D11: id | E11: reference | F11: year | G11: desc_es | H11: desc_en | I11: label_es | J11: label_en | K11: code label_en | L11: Agent-Based Model Analysis | M11: Archival Analysis | N11: Bibliometrics and Scientometrics | O11: Bioinformatics Tools | P11: Cluster Analysis | Q11: Computational Qualitative Analysis | R11: Correspondence Analysis | S11: Digital Source Mining | T11: Direct Observation of Behavior | U11: Document Analysis | V11: Ethnography | W11: Formal Concept Analysis | X11: Genetic Analysis | Y11: Inductive Game Theory | Z11: Interviews | AA11: Linear Regression | AB11: Literature Review | AC11: Machine Learning | AD11: Multiplex Network Analysis | AE11: Network Visualization | AF11: Pattern Recognition | AG11: Reconstruction of Genealogies and Trajectories | AH11: Sentiment Analysis | AI11: Software Engineering | AJ11: Social Networks Analysis | AK11: Surveys | AL11: Technical Analysis | AM11: Topic Modeling Analysis
D12: =VLOOKUP($K12,cat_object!$A$2:$H$1005,2,0) -> 1001 | E12: =VLOOKUP($K12,cat_object!$A$2:$H$1005,7,0) -> 0 | F12: =VLOOKUP($K12,cat_object!$A$2:$H$1005,8,0) -> 0 | G12: =VLOOKUP($K12,cat_object!$A$2:$H$1005,6,0) -> Alejandro Arnulfo Ruiz León | H12: =VLOOKUP($K12,cat_object!$A$2:$H$1005,5,0) -> Alejandro Arnulfo Ruiz León | I12: =VLOOKUP($K12,cat_object!$A$2:$H$1005,4,0) -> Alejandro Ruiz | J12: =VLOOKUP($K12,cat_object!$A$2:$H$1005,3,0) -> Alejandro Ruiz | K12: Alejandro_Ruiz | L12: 0 | M12: 0 | N12: 1 | O12: 0 | P12: 0 | Q12: 0 | R12: 0 | S12: 0 | T12: 0 | U12: 1 | V12: 0 | W12: 0 | X12: 0 | Y12: 0 | Z12: 1 | AA12: 0 | AB12: 1 | AC12: 0 | AD12: 1 | AE12: 1 | AF12: 0 | AG12: 0 | AH12: 0 | AI12: 0 | AJ12: 1 | AK12: 1 | AL12: 0 | AM12: 0
D13: =VLOOKUP($K13,cat_object!$A$2:$H$1005,2,0) -> 1002 | E13: =VLOOKUP($K13,cat_object!$A$2:$H$1005,7,0) -> 0 | F13: =VLOOKUP($K13,cat_object!$A$2:$H$1005,8,0) -> 0 | G13: =VLOOKUP($K13,cat_object!$A$2:$H$1005,6,0) -> Aline Amor Saldaña Sánchez | H13: =VLOOKUP($K13,cat_object!$A$2:$H$1005,5,0) -> Aline Amor Saldaña Sánchez | I13: =VLOOKUP($K13,cat_object!$A$2:$H$1005,4,0) -> Aline Saldaña | J13: =VLOOKUP($K13,cat_object!$A$2:$H$1005,3,0) -> Aline Saldaña | K13: Aline_Saldaña | L13: 0 | M13: 0 | N13: 0 | O13: 0 | P13: 0 | Q13: 0 | R13: 0 | S13: 0 | T13: 1 | U13: 0 | V13: 0 | W13: 0 | X13: 0 | Y13: 0 | Z13: 0 | AA13: 0 | AB13: 0 | AC13: 0 | AD13: 1 | AE13: 0 | AF13: 0 | AG13: 0 | AH13: 0 | AI13: 0 | AJ13: 1 | AK13: 0 | AL13: 0 | AM13: 0
D14: =VLOOKUP($K14,cat_object!$A$2:$H$1005,2,0) -> 1003 | E14: =VLOOKUP($K14,cat_object!$A$2:$H$1005,7,0) -> 0 | F14: =VLOOKUP($K14,cat_object!$A$2:$H$1005,8,0) -> 0 | G14: =VLOOKUP($K14,cat_object!$A$2:$H$1005,6,0) -> Ana María Medeles Hernández | H14: =VLOOKUP($K14,cat_object!$A$2:$H$1005,5,0) -> Ana María Medeles Hernández | I14: =VLOOKUP($K14,cat_object!$A$2:$H$1005,4,0) -> Ana Medeles | J14: =VLOOKUP($K14,cat_object!$A$2:$H$1005,3,0) -> Ana Medeles | K14: Ana_Medeles | L14: 0 | M14: 1 | N14: 0 | O14: 0 | P14: 0 | Q14: 0 | R14: 0 | S14: 1 | T14: 0 | U14: 0 | V14: 0 | W14: 0 | X14: 0 | Y14: 0 | Z14: 0 | AA14: 0 | AB14: 0 | AC14: 0 | AD14: 0 | AE14: 0 | AF14: 0 | AG14: 0 | AH14: 0 | AI14: 0 | AJ14: 0 | AK14: 0 | AL14: 0 | AM14: 0
D15: =VLOOKUP($K15,cat_object!$A$2:$H$1005,2,0) -> 1004 | E15: =VLOOKUP($K15,cat_object!$A$2:$H$1005,7,0) -> 0 | F15: =VLOOKUP($K15,cat_object!$A$2:$H$1005,8,0) -> 0 | G15: =VLOOKUP($K15,cat_object!$A$2:$H$1005,6,0) -> Carlos Rodríguez Contreras | H15: =VLOOKUP($K15,cat_object!$A$2:$H$1005,5,0) -> Carlos Rodríguez Contreras | I15: =VLOOKUP($K15,cat_object!$A$2:$H$1005,4,0) -> Carlos Rodriguez | J15: =VLOOKUP($K15,cat_object!$A$2:$H$1005,3,0) -> Carlos Rodriguez | K15: Carlos_Rodriguez | L15: 0 | M15: 0 | N15: 0 | O15: 0 | P15: 0 | Q15: 0 | R15: 0 | S15: 1 | T15: 0 | U15: 0 | V15: 0 | W15: 0 | X15: 0 | Y15: 0 | Z15: 0 | AA15: 0 | AB15: 0 | AC15: 1 | AD15: 0 | AE15: 0 | AF15: 0 | AG15: 0 | AH15: 1 | AI15: 0 | AJ15: 0 | AK15: 0 | AL15: 1 | AM15: 0
D16: =VLOOKUP($K16,cat_object!$A$2:$H$1005,2,0) -> 1005 | E16: =VLOOKUP($K16,cat_object!$A$2:$H$1005,7,0) -> 0 | F16: =VLOOKUP($K16,cat_object!$A$2:$H$1005,8,0) -> 0 | G16: =VLOOKUP($K16,cat_object!$A$2:$H$1005,6,0) -> Cristina Jasso del Toro | H16: =VLOOKUP($K16,cat_object!$A$2:$H$1005,5,0) -> Cristina Jasso del Toro | I16: =VLOOKUP($K16,cat_object!$A$2:$H$1005,4,0) -> Cristina Jasso | J16: =VLOOKUP($K16,cat_object!$A$2:$H$1005,3,0) -> Cristina Jasso | K16: Cristina_Jasso | L16: 0 | M16: 0 | N16: 0 | O16: 1 | P16: 0 | Q16: 0 | R16: 0 | S16: 0 | T16: 1 | U16: 0 | V16: 0 | W16: 0 | X16: 1 | Y16: 0 | Z16: 0 | AA16: 0 | AB16: 0 | AC16: 0 | AD16: 0 | AE16: 1 | AF16: 0 | AG16: 0 | AH16: 0 | AI16: 0 | AJ16: 1 | AK16: 0 | AL16: 0 | AM16: 0
D17: =VLOOKUP($K17,cat_object!$A$2:$H$1005,2,0) -> 1011 | E17: =VLOOKUP($K17,cat_object!$A$2:$H$1005,7,0) -> 0 | F17: =VLOOKUP($K17,cat_object!$A$2:$H$1005,8,0) -> 0 | G17: =VLOOKUP($K17,cat_object!$A$2:$H$1005,6,0) -> Gabriela Elisa Sued | H17: =VLOOKUP($K17,cat_object!$A$2:$H$1005,5,0) -> Gabriela Elisa Sued | I17: =VLOOKUP($K17,cat_object!$A$2:$H$1005,4,0) -> Gabriela Sued | J17: =VLOOKUP($K17,cat_object!$A$2:$H$1005,3,0) -> Gabriela Sued | K17: Gabriela_Sued | L17: 0 | M17: 0 | N17: 1 | O17: 0 | P17: 0 | Q17: 0 | R17: 0 | S17: 0 | T17: 0 | U17: 1 | V17: 0 | W17: 0 | X17: 0 | Y17: 0 | Z17: 1 | AA17: 0 | AB17: 0 | AC17: 0 | AD17: 0 | AE17: 0 | AF17: 0 | AG17: 0 | AH17: 0 | AI17: 0 | AJ17: 0 | AK17: 0 | AL17: 0 | AM17: 0
D18: =VLOOKUP($K18,cat_object!$A$2:$H$1005,2,0) -> 1010 | E18: =VLOOKUP($K18,cat_object!$A$2:$H$1005,7,0) -> 0 | F18: =VLOOKUP($K18,cat_object!$A$2:$H$1005,8,0) -> 0 | G18: =VLOOKUP($K18,cat_object!$A$2:$H$1005,6,0) -> Gabriel Ramos Fernández | H18: =VLOOKUP($K18,cat_object!$A$2:$H$1005,5,0) -> Gabriel Ramos Fernández | I18: =VLOOKUP($K18,cat_object!$A$2:$H$1005,4,0) -> Gabriel Ramos | J18: =VLOOKUP($K18,cat_object!$A$2:$H$1005,3,0) -> Gabriel Ramos | K18: Gabriel_Ramos | L18: 1 | M18: 0 | N18: 0 | O18: 0 | P18: 0 | Q18: 0 | R18: 0 | S18: 0 | T18: 1 | U18: 0 | V18: 0 | W18: 0 | X18: 0 | Y18: 1 | Z18: 0 | AA18: 0 | AB18: 0 | AC18: 0 | AD18: 1 | AE18: 1 | AF18: 0 | AG18: 0 | AH18: 0 | AI18: 0 | AJ18: 1 | AK18: 0 | AL18: 0 | AM18: 0
D19: =VLOOKUP($K19,cat_object!$A$2:$H$1005,2,0) -> 1015 | E19: =VLOOKUP($K19,cat_object!$A$2:$H$1005,7,0) -> 0 | F19: =VLOOKUP($K19,cat_object!$A$2:$H$1005,8,0) -> 0 | G19: =VLOOKUP($K19,cat_object!$A$2:$H$1005,6,0) -> Israel García Solares | H19: =VLOOKUP($K19,cat_object!$A$2:$H$1005,5,0) -> Israel García Solares | I19: =VLOOKUP($K19,cat_object!$A$2:$H$1005,4,0) -> Israel García | J19: =VLOOKUP($K19,cat_object!$A$2:$H$1005,3,0) -> Israel García | K19: Israel_Garcia | L19: 0 | M19: 1 | N19: 0 | O19: 0 | P19: 1 | Q19: 1 | R19: 1 | S19: 0 | T19: 0 | U19: 1 | V19: 0 | W19: 0 | X19: 0 | Y19: 0 | Z19: 0 | AA19: 1 | AB19: 0 | AC19: 0 | AD19: 0 | AE19: 1 | AF19: 1 | AG19: 0 | AH19: 0 | AI19: 0 | AJ19: 1 | AK19: 0 | AL19: 0 | AM19: 0
D20: =VLOOKUP($K20,cat_object!$A$2:$H$1005,2,0) -> 1016 | E20: =VLOOKUP($K20,cat_object!$A$2:$H$1005,7,0) -> 0 | F20: =VLOOKUP($K20,cat_object!$A$2:$H$1005,8,0) -> 0 | G20: =VLOOKUP($K20,cat_object!$A$2:$H$1005,6,0) -> Israel Sandoval Grajeda | H20: =VLOOKUP($K20,cat_object!$A$2:$H$1005,5,0) -> Israel Sandoval Grajeda | I20: =VLOOKUP($K20,cat_object!$A$2:$H$1005,4,0) -> Israel Sandoval | J20: =VLOOKUP($K20,cat_object!$A$2:$H$1005,3,0) -> Israel Sandoval | K20: Israel_Sandoval | L20: 0 | M20: 0 | N20: 0 | O20: 0 | P20: 0 | Q20: 0 | R20: 0 | S20: 0 | T20: 0 | U20: 0 | V20: 0 | W20: 0 | X20: 0 | Y20: 0 | Z20: 0 | AA20: 0 | AB20: 0 | AC20: 0 | AD20: 0 | AE20: 0 | AF20: 0 | AG20: 1 | AH20: 0 | AI20: 1 | AJ20: 0 | AK20: 0 | AL20: 0 | AM20: 0
D21: =VLOOKUP($K21,cat_object!$A$2:$H$1005,2,0) -> 1021 | E21: =VLOOKUP($K21,cat_object!$A$2:$H$1005,7,0) -> 0 | F21: =VLOOKUP($K21,cat_object!$A$2:$H$1005,8,0) -> 0 | G21: =VLOOKUP($K21,cat_object!$A$2:$H$1005,6,0) -> José Arturo López Pérez | H21: =VLOOKUP($K21,cat_object!$A$2:$H$1005,5,0) -> José Arturo López Pérez | I21: =VLOOKUP($K21,cat_object!$A$2:$H$1005,4,0) -> Arturo López | J21: =VLOOKUP($K21,cat_object!$A$2:$H$1005,3,0) -> Arturo López | K21: Arturo_Lopez | L21: 0 | M21: 0 | N21: 1 | O21: 0 | P21: 0 | Q21: 0 | R21: 0 | S21: 1 | T21: 0 | U21: 0 | V21: 0 | W21: 0 | X21: 0 | Y21: 0 | Z21: 0 | AA21: 0 | AB21: 0 | AC21: 0 | AD21: 1 | AE21: 1 | AF21: 0 | AG21: 0 | AH21: 1 | AI21: 0 | AJ21: 1 | AK21: 0 | AL21: 0 | AM21: 1
D22: =VLOOKUP($K22,cat_object!$A$2:$H$1005,2,0) -> 1029 | E22: =VLOOKUP($K22,cat_object!$A$2:$H$1005,7,0) -> 0 | F22: =VLOOKUP($K22,cat_object!$A$2:$H$1005,8,0) -> 2024-2026 | G22: =VLOOKUP($K22,cat_object!$A$2:$H$1005,6,0) -> Liliana Ramírez Ruíz | H22: =VLOOKUP($K22,cat_object!$A$2:$H$1005,5,0) -> Liliana Ramírez Ruíz | I22: =VLOOKUP($K22,cat_object!$A$2:$H$1005,4,0) -> Liliana Ramírez | J22: =VLOOKUP($K22,cat_object!$A$2:$H$1005,3,0) -> Liliana Ramírez | K22: Liliana_Ramirez | L22: 0 | M22: 0 | N22: 1 | O22: 0 | P22: 0 | Q22: 0 | R22: 0 | S22: 0 | T22: 0 | U22: 0 | V22: 1 | W22: 0 | X22: 0 | Y22: 0 | Z22: 1 | AA22: 0 | AB22: 0 | AC22: 0 | AD22: 0 | AE22: 0 | AF22: 0 | AG22: 0 | AH22: 0 | AI22: 0 | AJ22: 1 | AK22: 0 | AL22: 0 | AM22: 0
D23: =VLOOKUP($K23,cat_object!$A$2:$H$1005,2,0) -> 1035 | E23: =VLOOKUP($K23,cat_object!$A$2:$H$1005,7,0) -> https://mmss.iimas.unam.mx/posdoctorales/dra-mariana-espinosa-aldama/ | F23: =VLOOKUP($K23,cat_object!$A$2:$H$1005,8,0) -> 2024-2028 | G23: =VLOOKUP($K23,cat_object!$A$2:$H$1005,6,0) -> Mariana Espinosa Aldama | H23: =VLOOKUP($K23,cat_object!$A$2:$H$1005,5,0) -> Mariana Espinosa Aldama | I23: =VLOOKUP($K23,cat_object!$A$2:$H$1005,4,0) -> Mariana Espinosa | J23: =VLOOKUP($K23,cat_object!$A$2:$H$1005,3,0) -> Mariana Espinosa | K23: Mariana_Espinosa | L23: 0 | M23: 0 | N23: 1 | O23: 0 | P23: 0 | Q23: 0 | R23: 0 | S23: 0 | T23: 0 | U23: 0 | V23: 0 | W23: 1 | X23: 0 | Y23: 0 | Z23: 0 | AA23: 0 | AB23: 1 | AC23: 0 | AD23: 0 | AE23: 1 | AF23: 0 | AG23: 0 | AH23: 0 | AI23: 0 | AJ23: 0 | AK23: 0 | AL23: 0 | AM23: 1
... D31: =VLOOKUP($K31,cat_object!$A$2:$H$1005,2,0) -> 1023 | E31: =VLOOKUP($K31,cat_object!$A$2:$H$1005,7,0) -> 0 | F31: =VLOOKUP($K31,cat_object!$A$2:$H$1005,8,0) -> 0 | G31: =VLOOKUP($K31,cat_object!$A$2:$H$1005,6,0) -> Juan Carlos Escalante Leal | H31: =VLOOKUP($K31,cat_object!$A$2:$H$1005,5,0) -> Juan Carlos Escalante Leal | I31: =VLOOKUP($K31,cat_object!$A$2:$H$1005,4,0) -> Juan Escalante | J31: =VLOOKUP($K31,cat_object!$A$2:$H$1005,3,0) -> Juan Escalante | K31: Juan_Escalante | L31: 0 | M31: 0 | N31: 0 | O31: 0 | P31: 0 | Q31: 0 | R31: 0 | S31: 0 | T31: 0 | U31: 0 | V31: 0 | W31: 0 | X31: 0 | Y31: 0 | Z31: 1 | AA31: 0 | AB31: 1 | AC31: 0 | AD31: 0 | AE31: 1 | AF31: 0 | AG31: 0 | AH31: 0 | AI31: 0 | AJ31: 0 | AK31: 0 | AL31: 0 | AM31: 0

Sheet Objetos
A1: Context: | B1: =VLOOKUP($C$1,cat_context!$A$2:$B$1001,2,0) -> 3 | C1: Objetos
J2: Attributes | K2: id | L2: =VLOOKUP(L$11,cat_attribute!$A$2:$M$1001,2,0) -> 5061 | M2: =VLOOKUP(M$11,cat_attribute!$A$2:$M$1001,2,0) -> 5062 | N2: =VLOOKUP(N$11,cat_attribute!$A$2:$M$1001,2,0) -> 5063 | O2: =VLOOKUP(O$11,cat_attribute!$A$2:$M$1001,2,0) -> 5064 | P2: =VLOOKUP(P$11,cat_attribute!$A$2:$M$1001,2,0) -> 5065 | Q2: =VLOOKUP(Q$11,cat_attribute!$A$2:$M$1001,2,0) -> 5066 | R2: =VLOOKUP(R$11,cat_attribute!$A$2:$M$1001,2,0) -> 5067 | S2: =VLOOKUP(S$11,cat_attribute!$A$2:$M$1001,2,0) -> 5068 | ... AF2: =VLOOKUP(AF$11,cat_attribute!$A$2:$M$1001,2,0) -> 5082
K3: reference | L3: =VLOOKUP(L$11,cat_attribute!$A$2:$K$1001,11,0) -> 0 | M3: =VLOOKUP(M$11,cat_attribute!$A$2:$K$1001,11,0) -> 0 | N3: =VLOOKUP(N$11,cat_attribute!$A$2:$K$1001,11,0) -> 0 | O3: =VLOOKUP(O$11,cat_attribute!$A$2:$K$1001,11,0) -> 0 | P3: =VLOOKUP(P$11,cat_attribute!$A$2:$K$1001,11,0) -> 0 | Q3: =VLOOKUP(Q$11,cat_attribute!$A$2:$K$1001,11,0) -> 0 | R3: =VLOOKUP(R$11,cat_attribute!$A$2:$K$1001,11,0) -> 0 | S3: =VLOOKUP(S$11,cat_attribute!$A$2:$K$1001,11,0) -> 0 | ... AF3: =VLOOKUP(AF$11,cat_attribute!$A$2:$K$1001,11,0) -> 0
K4: explanation_es | L4: =VLOOKUP(L$11,cat_attribute!$A$2:$M$1001,12,0) -> 0 | M4: =VLOOKUP(M$11,cat_attribute!$A$2:$M$1001,12,0) -> 0 | N4: =VLOOKUP(N$11,cat_attribute!$A$2:$M$1001,12,0) -> 0 | O4: =VLOOKUP(O$11,cat_attribute!$A$2:$M$1001,12,0) -> 0 | P4: =VLOOKUP(P$11,cat_attribute!$A$2:$M$1001,12,0) -> 0 | Q4: =VLOOKUP(Q$11,cat_attribute!$A$2:$M$1001,12,0) -> 0 | R4: =VLOOKUP(R$11,cat_attribute!$A$2:$M$1001,12,0) -> 0 | S4: =VLOOKUP(S$11,cat_attribute!$A$2:$M$1001,12,0) -> 0 | ... AF4: =VLOOKUP(AF$11,cat_attribute!$A$2:$M$1001,12,0) -> 0
K5: explanation_en | L5: =VLOOKUP(L$11,cat_attribute!$A$2:$K$1001,11,0) -> 0 | M5: =VLOOKUP(M$11,cat_attribute!$A$2:$K$1001,11,0) -> 0 | N5: =VLOOKUP(N$11,cat_attribute!$A$2:$K$1001,11,0) -> 0 | O5: =VLOOKUP(O$11,cat_attribute!$A$2:$K$1001,11,0) -> 0 | P5: =VLOOKUP(P$11,cat_attribute!$A$2:$K$1001,11,0) -> 0 | Q5: =VLOOKUP(Q$11,cat_attribute!$A$2:$K$1001,11,0) -> 0 | R5: =VLOOKUP(R$11,cat_attribute!$A$2:$K$1001,11,0) -> 0 | S5: =VLOOKUP(S$11,cat_attribute!$A$2:$K$1001,11,0) -> 0 | ... AF5: =VLOOKUP(AF$11,cat_attribute!$A$2:$K$1001,11,0) -> 0
K6: formula | L6: =VLOOKUP(L$11,cat_attribute!$A$2:$K$1001,10,0) -> 0 | M6: =VLOOKUP(M$11,cat_attribute!$A$2:$K$1001,10,0) -> 0 | N6: =VLOOKUP(N$11,cat_attribute!$A$2:$K$1001,10,0) -> 0 | O6: =VLOOKUP(O$11,cat_attribute!$A$2:$K$1001,10,0) -> 0 | P6: =VLOOKUP(P$11,cat_attribute!$A$2:$K$1001,10,0) -> 0 | Q6: =VLOOKUP(Q$11,cat_attribute!$A$2:$K$1001,10,0) -> 0 | R6: =VLOOKUP(R$11,cat_attribute!$A$2:$K$1001,10,0) -> 0 | S6: =VLOOKUP(S$11,cat_attribute!$A$2:$K$1001,10,0) -> 0 | ... AF6: =VLOOKUP(AF$11,cat_attribute!$A$2:$K$1001,10,0) -> 0
K7: title_es | L7: =VLOOKUP(L$11,cat_attribute!$A$2:$M$1001,9,0) -> Entidades, Espacios y Redes Académicas | M7: =VLOOKUP(M$11,cat_attribute!$A$2:$M$1001,9,0) -> Redes agroalimentarias | N7: =VLOOKUP(N$11,cat_attribute!$A$2:$M$1001,9,0) -> Inteligencia artificial | O7: =VLOOKUP(O$11,cat_attribute!$A$2:$M$1001,9,0) -> Astronomía, Cosmología y Gravitación | P7: =VLOOKUP(P$11,cat_attribute!$A$2:$M$1001,9,0) -> Las categorías y clasificaciones de medición social | Q7: =VLOOKUP(Q$11,cat_attribute!$A$2:$M$1001,9,0) -> Cetáceos | R7: =VLOOKUP(R$11,cat_attribute!$A$2:$M$1001,9,0) -> Cambio climático | S7: =VLOOKUP(S$11,cat_attribute!$A$2:$M$1001,9,0) -> Cotejos de Documentos y fuentes de información | ... AF7: =VLOOKUP(AF$11,cat_attribute!$A$2:$M$1001,9,0) -> La promoción y publicidad turística
K8: title_en | L8: =VLOOKUP(L$11,cat_attribute!$A$2:$M$1001,9,0) -> Entidades, Espacios y Redes Académicas | M8: =VLOOKUP(M$11,cat_attribute!$A$2:$M$1001,9,0) -> Redes agroalimentarias | N8: =VLOOKUP(N$11,cat_attribute!$A$2:$M$1001,9,0) -> Inteligencia artificial | O8: =VLOOKUP(O$11,cat_attribute!$A$2:$M$1001,9,0) -> Astronomía, Cosmología y Gravitación | P8: =VLOOKUP(P$11,cat_attribute!$A$2:$M$1001,9,0) -> Las categorías y clasificaciones de medición social | Q8: =VLOOKUP(Q$11,cat_attribute!$A$2:$M$1001,9,0) -> Cetáceos | R8: =VLOOKUP(R$11,cat_attribute!$A$2:$M$1001,9,0) -> Cambio climático | S8: =VLOOKUP(S$11,cat_attribute!$A$2:$M$1001,9,0) -> Cotejos de Documentos y fuentes de información | ... AF8: =VLOOKUP(AF$11,cat_attribute!$A$2:$M$1001,9,0) -> La promoción y publicidad turística
K9: class_code | L9: =VLOOKUP(L$11,cat_attribute!$A$2:$M$1001,7,0) -> Objeto | M9: =VLOOKUP(M$11,cat_attribute!$A$2:$M$1001,7,0) -> Objeto | N9: =VLOOKUP(N$11,cat_attribute!$A$2:$M$1001,7,0) -> Objeto | O9: =VLOOKUP(O$11,cat_attribute!$A$2:$M$1001,7,0) -> Objeto | P9: =VLOOKUP(P$11,cat_attribute!$A$2:$M$1001,7,0) -> Objeto | Q9: =VLOOKUP(Q$11,cat_attribute!$A$2:$M$1001,7,0) -> Objeto | R9: =VLOOKUP(R$11,cat_attribute!$A$2:$M$1001,7,0) -> Objeto | S9: =VLOOKUP(S$11,cat_attribute!$A$2:$M$1001,7,0) -> Objeto | ... AF9: =VLOOKUP(AF$11,cat_attribute!$A$2:$M$1001,7,0) -> Objeto
D10: Objects | K10: label_es | L10: =VLOOKUP(L$11,cat_attribute!$A$2:$M$1001,3,0) -> Entidades Academicas | M10: =VLOOKUP(M$11,cat_attribute!$A$2:$M$1001,3,0) -> Redes agroalimentarias | N10: =VLOOKUP(N$11,cat_attribute!$A$2:$M$1001,3,0) -> Inteligencia artificial | O10: =VLOOKUP(O$11,cat_attribute!$A$2:$M$1001,3,0) -> Astronomia | P10: =VLOOKUP(P$11,cat_attribute!$A$2:$M$1001,3,0) -> Medicion social | Q10: =VLOOKUP(Q$11,cat_attribute!$A$2:$M$1001,3,0) -> Cetaceos | R10: =VLOOKUP(R$11,cat_attribute!$A$2:$M$1001,3,0) -> Cambio climático | S10: =VLOOKUP(S$11,cat_attribute!$A$2:$M$1001,3,0) -> Cotejos de Documentos | ... AF10: =VLOOKUP(AF$11,cat_attribute!$A$2:$M$1001,3,0) -> Turísmo
D11: id | E11: reference | F11: year | G11: desc_es | H11: desc_en | I11: label_es | J11: label_en | K11: code label_en | L11: Academic entities | M11: Agri-food Networks | N11: Artificial Intelligence | O11: Astronomy | P11: Social Measurement | Q11: Cetaceans | R11: Climate Change | S11: Information Sources | T11: COVID-19 | U11: Trajectories of Science | V11: Digital News | W11: Digital Technologies | X11: Economic System | Y11: Collective Tasks | Z11: Human Vocal Interactions | AA11: Statistical Practices | AB11: Nanotechnology | AC11: Socio-ecosystems in Yucatán | AD11: Spider Monkeys | AE11: Studies of Scientists | AF11: Tourism
D12: =VLOOKUP($K12,cat_object!$A$2:$H$1005,2,0) -> 1001 | E12: =VLOOKUP($K12,cat_object!$A$2:$H$1005,7,0) -> 0 | F12: =VLOOKUP($K12,cat_object!$A$2:$H$1005,8,0) -> 0 | G12: =VLOOKUP($K12,cat_object!$A$2:$H$1005,6,0) -> Alejandro Arnulfo Ruiz León | H12: =VLOOKUP($K12,cat_object!$A$2:$H$1005,5,0) -> Alejandro Arnulfo Ruiz León | I12: =VLOOKUP($K12,cat_object!$A$2:$H$1005,4,0) -> Alejandro Ruiz | J12: =VLOOKUP($K12,cat_object!$A$2:$H$1005,3,0) -> Alejandro Ruiz | K12: Alejandro_Ruiz | L12: 1 | M12: 0 | N12: 0 | O12: 1 | P12: 0 | Q12: 0 | R12: 0 | S12: 0 | T12: 0 | U12: 1 | V12: 0 | W12: 0 | X12: 0 | Y12: 0 | Z12: 0 | AA12: 0 | AB12: 0 | AC12: 0 | AD12: 0 | AE12: 1 | AF12: 1
D13: =VLOOKUP($K13,cat_object!$A$2:$H$1005,2,0) -> 1002 | E13: =VLOOKUP($K13,cat_object!$A$2:$H$1005,7,0) -> 0 | F13: =VLOOKUP($K13,cat_object!$A$2:$H$1005,8,0) -> 0 | G13: =VLOOKUP($K13,cat_object!$A$2:$H$1005,6,0) -> Aline Amor Saldaña Sánchez | H13: =VLOOKUP($K13,cat_object!$A$2:$H$1005,5,0) -> Aline Amor Saldaña Sánchez | I13: =VLOOKUP($K13,cat_object!$A$2:$H$1005,4,0) -> Aline Saldaña | J13: =VLOOKUP($K13,cat_object!$A$2:$H$1005,3,0) -> Aline Saldaña | K13: Aline_Saldaña | L13: 0 | M13: 0 | N13: 0 | O13: 0 | P13: 0 | Q13: 0 | R13: 0 | S13: 0 | T13: 0 | U13: 0 | V13: 0 | W13: 0 | X13: 0 | Y13: 0 | Z13: 0 | AA13: 0 | AB13: 0 | AC13: 0 | AD13: 1 | AE13: 0 | AF13: 0
D14: =VLOOKUP($K14,cat_object!$A$2:$H$1005,2,0) -> 1003 | E14: =VLOOKUP($K14,cat_object!$A$2:$H$1005,7,0) -> 0 | F14: =VLOOKUP($K14,cat_object!$A$2:$H$1005,8,0) -> 0 | G14: =VLOOKUP($K14,cat_object!$A$2:$H$1005,6,0) -> Ana María Medeles Hernández | H14: =VLOOKUP($K14,cat_object!$A$2:$H$1005,5,0) -> Ana María Medeles Hernández | I14: =VLOOKUP($K14,cat_object!$A$2:$H$1005,4,0) -> Ana Medeles | J14: =VLOOKUP($K14,cat_object!$A$2:$H$1005,3,0) -> Ana Medeles | K14: Ana_Medeles | L14: 0 | M14: 0 | N14: 0 | O14: 0 | P14: 1 | Q14: 0 | R14: 0 | S14: 0 | T14: 0 | U14: 0 | V14: 0 | W14: 0 | X14: 0 | Y14: 0 | Z14: 0 | AA14: 1 | AB14: 0 | AC14: 0 | AD14: 0 | AE14: 0 | AF14: 0
D15: =VLOOKUP($K15,cat_object!$A$2:$H$1005,2,0) -> 1004 | E15: =VLOOKUP($K15,cat_object!$A$2:$H$1005,7,0) -> 0 | F15: =VLOOKUP($K15,cat_object!$A$2:$H$1005,8,0) -> 0 | G15: =VLOOKUP($K15,cat_object!$A$2:$H$1005,6,0) -> Carlos Rodríguez Contreras | H15: =VLOOKUP($K15,cat_object!$A$2:$H$1005,5,0) -> Carlos Rodríguez Contreras | I15: =VLOOKUP($K15,cat_object!$A$2:$H$1005,4,0) -> Carlos Rodriguez | J15: =VLOOKUP($K15,cat_object!$A$2:$H$1005,3,0) -> Carlos Rodriguez | K15: Carlos_Rodriguez | L15: 0 | M15: 0 | N15: 0 | O15: 0 | P15: 0 | Q15: 0 | R15: 0 | S15: 0 | T15: 0 | U15: 0 | V15: 1 | W15: 0 | X15: 1 | Y15: 0 | Z15: 0 | AA15: 0 | AB15: 0 | AC15: 0 | AD15: 0 | AE15: 0 | AF15: 0
D16: =VLOOKUP($K16,cat_object!$A$2:$H$1005,2,0) -> 1005 | E16: =VLOOKUP($K16,cat_object!$A$2:$H$1005,7,0) -> 0 | F16: =VLOOKUP($K16,cat_object!$A$2:$H$1005,8,0) -> 0 | G16: =VLOOKUP($K16,cat_object!$A$2:$H$1005,6,0) -> Cristina Jasso del Toro | H16: =VLOOKUP($K16,cat_object!$A$2:$H$1005,5,0) -> Cristina Jasso del Toro | I16: =VLOOKUP($K16,cat_object!$A$2:$H$1005,4,0) -> Cristina Jasso | J16: =VLOOKUP($K16,cat_object!$A$2:$H$1005,3,0) -> Cristina Jasso | K16: Cristina_Jasso | L16: 0 | M16: 0 | N16: 0 | O16: 0 | P16: 0 | Q16: 0 | R16: 0 | S16: 0 | T16: 0 | U16: 0 | V16: 0 | W16: 0 | X16: 0 | Y16: 0 | Z16: 0 | AA16: 0 | AB16: 0 | AC16: 0 | AD16: 1 | AE16: 0 | AF16: 0
